<robot name ='gypsy'>
	
   </link> 
    <link name = 'base_link'>
       <inertial>
            <mass value ='6.398'/>
            <origin xyz ='0 0 0' rpy ='0 0 0'/>
            <inertia ixx='0.204770122667' iyy='0.204770122667' izz='0.163857045333' ixy='0.0' ixz ='0.0' iyz='0.0'/>
        </inertial>
        <collision>
            <origin xyz ='0 0 0' rpy ='0 0 0'/>
            <geometry>
                   <box size = "0.392 0.392 0.45"/>
            </geometry>
        </collision>
    </link>



<link name = 'r_wheel'>
		<inertial>
            <mass value ='0.2'/>
            <origin xyz ='0 0 0' rpy ='0 0 0'/>
            <inertia ixx='0.000133066666667' iyy='0.000133066666667' izz='0.00025' ixy='0.0' ixz ='0.0' iyz='0.0'/>
        </inertial>
        <collision>
            <origin xyz ='0 0 0' rpy ='0 0 0'/>
            <geometry>
               <cylinder radius = '0.05' length ='0.022'/>
            </geometry>
        </collision>
        <visual>
            <origin xyz =  '0 0 0' rpy ='0 0 0'/>
            <geometry>
                <cylinder radius = '0.05' length ='0.022'/>
            </geometry>
        </visual>
    </link>
 
    <joint name = 'r_wheel_joint' type ='continuous'>
        <parent link = 'base_link'/>
        <child link = 'r_wheel'/>
        <origin xyz = '0.1625 0 -0.2525' rpy = '0 1.57 0'/>
         <limit effort="0.1" velocity="0.01"/>
        <axis xyz ='0 0 1'/>
    </joint>



   <link name = 'l_wheel'>
		<inertial>
            <mass value ='0.2'/>
            <origin xyz ='0 0 0' rpy ='0 0 0'/>
            <inertia ixx='0.000133066666667' iyy='0.000133066666667' izz='0.00025' ixy='0.0' ixz ='0.0' iyz='0.0'/>
        </inertial>
        <collision>
            <origin xyz ='0 0 0' rpy ='0 0 0'/>
            <geometry>
               <cylinder radius = '0.05' length ='0.022'/>
                 
            </geometry>
        </collision>
       
        <visual>
            <origin xyz =  '0 0 0' rpy ='0 0 0'/>
            <geometry>
                <cylinder radius = '0.05' length ='0.022'/>
            </geometry>
        </visual>
    </link>

 
    <joint name = 'l_wheel_joint' type ='continuous'>
        <parent link = 'base_link'/>
        <child link = 'l_wheel'/>
        <origin xyz = '-0.1625 0 -0.2525' rpy = '0 1.57 0'/>
        <limit effort="0.1" velocity="0.01"/>
        <axis xyz ='0 0 1'/>
    </joint>






 <link name ='castor_front'>
		<inertial>
            <mass value ='0.2'/>
            <origin xyz ='0 0 0' rpy ='0 0 0'/>
            <inertia ixx='0.000152083333333' iyy='0.000123333333333' izz='0.000112083333333' ixy='0.0' ixz ='0.0' iyz='0.0'/>
        </inertial>
        <collision>
            <origin xyz ='0 0 0' rpy ='0 0 0'/>
            <geometry>
               <box size='0.025 0.05 0.07'/>
                 
            </geometry>
        </collision>
        <visual>
            <origin xyz ='0 0 0' rpy ='0 0 0'/>
            <geometry>
                <box size='0.025 0.05 0.07'/>
            </geometry>
        </visual>
    </link>

    <joint name='castor_front_joint' type='fixed'>
        <parent link = 'base_link'/>
        <child link = 'castor_front'/>
        
        <origin xyz ='0 0.1535  -0.2675' rpy ='0 0 0'/>
        
    </joint>


 <link name ='castor_back'>
		<inertial>
            <mass value ='0.2'/>
            <origin xyz ='0 0 0' rpy ='0 0 0'/>
            <inertia ixx='0.000152083333333' iyy='0.000123333333333' izz='0.000112083333333' ixy='0.0' ixz ='0.0' iyz='0.0'/>
        </inertial>
        <collision>
            <origin xyz ='0 0 0' rpy ='0 0 0'/>
            <geometry>
               <box size='0.025 0.05 0.07'/>
                 
            </geometry>
        </collision>
        <visual>
            <origin xyz ='0 0 0' rpy ='0 0 0'/>
            <geometry>
                <box size='0.025 0.05 0.07'/>
            </geometry>
        </visual>
    </link>


    <joint name='castor_back_joint' type='fixed'>
        <parent link = 'base_link'/>
        <child link = 'castor_back'/>
        
        <origin xyz ='0 -0.1535 -0.2675' rpy ='0 0 0'/>
        
    </joint>

 <link name = 'base_scan'>
        <inertial>
            <mass value ='0.216'/>
            <origin xyz ='0 0 0' rpy ='0 0 0'/>
            <inertia ixx='0.0001187235' iyy='0.0001187235' izz = '0.000128547' ixy='0.0' ixz ='0.0' iyz='0.0'/>
        </inertial>
        <collision>
            <origin xyz ='0 0 0' rpy ='0 0 0'/>
            <geometry>
                 <cylinder radius ='0.0345' length ='0.055'/>
            </geometry>
        </collision>
        <visual>	
            <origin xyz ='0 0 0' rpy ='0 0 0'/>
            <geometry>
                <cylinder radius ='0.0345' length ='0.055'/>
            </geometry>
        </visual>
    </link>

    <joint name = 'laser_joint' type ='fixed'>
        <parent link ='base_link'/>
        <child link = 'base_scan'/>
        <origin xyz ='0 0 0.19' rpy ='0 3.14 0'/>
    </joint>



<link name = 'imu_link'>
        <inertial>
            <mass value ='0.012'/>
            <origin xyz ='0 0 0' rpy ='0 0 0'/>
            <inertia ixx='2.5e-07' iyy='4.25e-07' izz = '6.25e-07' ixy='0.0' ixz ='0.0' iyz='0.0'/>
        </inertial>
        <collision>
            <origin xyz ='0 0 0' rpy ='0 0 0'/>
            <geometry>
                 <box size = '0.02 0.015 0.005'/>
            </geometry>
        </collision>
        <visual>
            <origin xyz ='0 0 0' rpy ='0 0 0'/>
            <geometry>
                <box size = '0.02 0.015 0.005'/>
            </geometry>
        </visual>
    </link>


 

    <joint name = 'imu_joint' type ='fixed'>
        <parent link ='base_link'/>
        <child link = 'imu_link'/>
        <origin xyz ='0 0 -0.225' rpy ='0 0 0'/>
    </joint>



   




   





 


</robot>

