<robot name ='raspbot'>
	   
  <material name="black">
    <color rgba="0.0 0.0 0.0 1.0"/>
  </material>
  <material name="blue">
    <color rgba="0.203125 0.23828125 0.28515625 1.0"/>
  </material>
  <material name="green">
    <color rgba="0.0 0.8 0.0 1.0"/>
  </material>
  <material name="grey">
    <color rgba="0.2 0.2 0.2 1.0"/>
  </material>
  <material name="orange">
    <color rgba="1.0 0.423529411765 0.0392156862745 1.0"/>
  </material>
  <material name="brown">
    <color rgba="0.870588235294 0.811764705882 0.764705882353 1.0"/>
  </material>
  <material name="red">
    <color rgba="0.80078125 0.12890625 0.1328125 1.0"/>
  </material>
  <material name="white">
    <color rgba="1.0 1.0 1.0 1.0"/>
  </material>  

  <gazebo reference="base_link">
    <material>Gazebo/Orange</material>
  </gazebo>
  <gazebo reference="link_left_wheel">
    <material>Gazebo/Blue</material>
  </gazebo>
  <gazebo reference="link_right_wheel">
    <material>Gazebo/Blue</material>
  </gazebo>
  <link name="base_link">
    <!-- pose and inertial -->
    <pose>0 0 0.1 0 0 0</pose>
    

  <link name = 'base_link'>
       <inertial>
            <mass value ='6.398'/>
            <origin xyz ='0 0 0' rpy ='0 0 0'/>
            <inertia ixx='0.204770122667' iyy='0.204770122667' izz='0.163857045333' ixy='0.0' ixz ='0.0' iyz='0.0'/>
        </inertial>
        <collision>
            <origin xyz ='0 0 0' rpy ='0 0 0'/>
            <geometry>
                   <box size = "0.392 0.392 0.45"/>
            </geometry>
        </collision>

 
         
    <visual>
      <origin rpy="0 0 0" xyz="0 0 0"/>
      <geometry>
        <box size="0.5 0.3 0.07"/>
      </geometry>
      <material name="blue"/>
    </visual>
    
  </link>

<link name = 'r_wheel'>
		<inertial>
            <mass value ='0.2'/>
            <origin xyz ='0 0 0' rpy ='0 0 0'/>
            <inertia ixx='0.000133066666667' iyy='0.000133066666667' izz='0.00025' ixy='0.0' ixz ='0.0' iyz='0.0'/>
        </inertial>
        <collision>
            <origin xyz ='0 0 0' rpy ='0 0 0'/>
            <geometry>
               <cylinder radius = '0.05' length ='0.022'/>
                 
            </geometry>
        </collision>
      
        <visual>
            <origin xyz =  '0 0 0' rpy ='0 0 0'/>
            <geometry>
                <cylinder radius = '0.05' length ='0.022'/>
            </geometry>
        </visual>
    </link>
 
    <joint name = 'r_wheel_joint' type ='continuous'>
        <parent link = 'base_link'/>
        <child link = 'r_wheel'/>
        <origin xyz = '0.1625 0 -0.2525' rpy = '0 1.57 0'/>
         <limit effort="0.1" velocity="0.01"/>
        <axis xyz ='0 0 1'/>
    </joint>



     <link name = 'l_wheel'>
		<inertial>
            <mass value ='0.2'/>
            <origin xyz ='0 0 0' rpy ='0 0 0'/>
            <inertia ixx='0.000133066666667' iyy='0.000133066666667' izz='0.00025' ixy='0.0' ixz ='0.0' iyz='0.0'/>
        </inertial>
        <collision>
            <origin xyz ='0 0 0' rpy ='0 0 0'/>
            <geometry>
               <cylinder radius = '0.05' length ='0.022'/>
                 
            </geometry>
        </collision>
       
        <visual>
            <origin xyz =  '0 0 0' rpy ='0 0 0'/>
            <geometry>
                <cylinder radius = '0.05' length ='0.022'/>
            </geometry>
        </visual>
    <joint name = 'l_wheel_joint' type ='continuous'>
        <parent link = 'base_link'/>
        <child link = 'l_wheel'/>
        <origin xyz = '-0.1625 0 -0.2525' rpy = '0 1.57 0'/>
        <limit effort="0.1" velocity="0.01"/>
        <axis xyz ='0 0 1'/>
    </joint>

    </link>
     <collision name="caster_front_collision">
      <origin rpy=" 0 0 0" xyz="0.35 0 -0.05"/>
      <geometry>
        <sphere radius="0.05"/>
      </geometry>
      <surface>
        <friction>
          <ode>
            <mu>0</mu>
            <mu2>0</mu2>
            <slip1>1.0</slip1>
            <slip2>1.0</slip2>
          </ode>
        </friction>
      </surface>
    </collision>
    <visual name="caster_front_visual">
      <origin rpy=" 0 0 0" xyz="0.2 0 -0.05"/>
      <geometry>
        <sphere radius="0.05"/>
      </geometry>
    </visual>
    </link>
 
   

  <link name="base_scan">
    <inertial>
      <origin xyz="0 0 0" rpy="0 0 0" />
      <mass value="1" />
      <!-- RANDOM INERTIA BELOW -->
      <inertia ixx='0.0001187235' iyy='0.0001187235' izz = '0.000128547' ixy='0.0' ixz ='0.0' iyz='0.0'/>
    </inertial>

    <visual>
      <origin xyz="0 0 0" rpy="0 0 0" />
      <geometry>
        <cylinder radius="0.05" length="0.1"/>
      </geometry>
      <material name="white" />
    </visual>

    <collision>
      <origin xyz="0 0 0" rpy="0 0 0"/>
      <geometry>
        <cylinder radius="0.05" length="0.1"/>
      </geometry>
    </collision>
  </link>

  <joint name="joint_sensor_laser" type="fixed">
    <origin xyz="0.15 0 0.05" rpy="0 0 0"/>
    <parent link="base_link"/>
    <child link="base_scan"/>
  </joint>



   




   





 


</robot>
